nbdev-proteomics
================

<!-- WARNING: THIS FILE WAS AUTOGENERATED! DO NOT EDIT! -->

``` python
```

    The autoreload extension is already loaded. To reload it, use:
      %reload_ext autoreload

A collection of utilities to process proteomics data

## Install

``` sh
pip install nbdev_proteomics
```

## How to use

Letâ€™s start by uploading a dataset from a DIA-NN analysis

``` python
normalize_dataframe
```

    <function nbdev_proteomics.dim_red.normalize_dataframe(in_df)>

``` python
plot_mds_columns
```

    <function nbdev_proteomics.dim_red.plot_mds_columns(in_df, colors, color_to_label)>

``` python
impute_proteomics_data
```

    <function nbdev_proteomics.impute_missing.impute_proteomics_data(df, conditions)>

``` python
DatasetAnalysis()
```

    <nbdev_proteomics.core.DatasetAnalysis>

``` python
# Initialize the class with the Spectronaut output file
# and a table to rename the columns
processor = SpectronautProcessor(
    "../toy_datasets/spectronaut_output.tsv",
    "../toy_datasets/spectronaut_column_mapping.tsv")

# Process the file and get the filtered protein quantification DataFrame
#filtered_quantification = processor.process()
#filtered_quantification.head()
```

    Unexpected exception formatting exception. Falling back to standard exception

    Traceback (most recent call last):
      File "/Users/MTinti/miniconda3/envs/mamba/envs/work_env2/lib/python3.9/site-packages/IPython/core/interactiveshell.py", line 3397, in run_code
        exec(code_obj, self.user_global_ns, self.user_ns)
      File "/var/folders/r1/gf3p5gjs5j9gw_49cj98r8b00000gp/T/ipykernel_12187/252438047.py", line 3, in <cell line: 3>
        processor = SpectronautProcessor(
      File "/Users/MTinti/git_projects/nbdev-proteomics/nbdev_proteomics/core.py", line 16, in __init__
        def analyse_missing_values(self, figsize=(8, 4)):
      File "/Users/MTinti/git_projects/nbdev-proteomics/nbdev_proteomics/core.py", line 45, in parse_column_mapping
    NameError: name 'pd' is not defined

    During handling of the above exception, another exception occurred:

    Traceback (most recent call last):
      File "/Users/MTinti/miniconda3/envs/mamba/envs/work_env2/lib/python3.9/site-packages/IPython/core/interactiveshell.py", line 1992, in showtraceback
        stb = self.InteractiveTB.structured_traceback(
      File "/Users/MTinti/miniconda3/envs/mamba/envs/work_env2/lib/python3.9/site-packages/IPython/core/ultratb.py", line 1118, in structured_traceback
        return FormattedTB.structured_traceback(
      File "/Users/MTinti/miniconda3/envs/mamba/envs/work_env2/lib/python3.9/site-packages/IPython/core/ultratb.py", line 1012, in structured_traceback
        return VerboseTB.structured_traceback(
      File "/Users/MTinti/miniconda3/envs/mamba/envs/work_env2/lib/python3.9/site-packages/IPython/core/ultratb.py", line 865, in structured_traceback
        formatted_exception = self.format_exception_as_a_whole(etype, evalue, etb, number_of_lines_of_context,
      File "/Users/MTinti/miniconda3/envs/mamba/envs/work_env2/lib/python3.9/site-packages/IPython/core/ultratb.py", line 818, in format_exception_as_a_whole
        frames.append(self.format_record(r))
      File "/Users/MTinti/miniconda3/envs/mamba/envs/work_env2/lib/python3.9/site-packages/IPython/core/ultratb.py", line 736, in format_record
        result += ''.join(_format_traceback_lines(frame_info.lines, Colors, self.has_colors, lvals))
      File "/Users/MTinti/miniconda3/envs/mamba/envs/work_env2/lib/python3.9/site-packages/stack_data/utils.py", line 145, in cached_property_wrapper
        value = obj.__dict__[self.func.__name__] = self.func(obj)
      File "/Users/MTinti/miniconda3/envs/mamba/envs/work_env2/lib/python3.9/site-packages/stack_data/core.py", line 698, in lines
        pieces = self.included_pieces
      File "/Users/MTinti/miniconda3/envs/mamba/envs/work_env2/lib/python3.9/site-packages/stack_data/utils.py", line 145, in cached_property_wrapper
        value = obj.__dict__[self.func.__name__] = self.func(obj)
      File "/Users/MTinti/miniconda3/envs/mamba/envs/work_env2/lib/python3.9/site-packages/stack_data/core.py", line 649, in included_pieces
        pos = scope_pieces.index(self.executing_piece)
      File "/Users/MTinti/miniconda3/envs/mamba/envs/work_env2/lib/python3.9/site-packages/stack_data/utils.py", line 145, in cached_property_wrapper
        value = obj.__dict__[self.func.__name__] = self.func(obj)
      File "/Users/MTinti/miniconda3/envs/mamba/envs/work_env2/lib/python3.9/site-packages/stack_data/core.py", line 628, in executing_piece
        return only(
      File "/Users/MTinti/miniconda3/envs/mamba/envs/work_env2/lib/python3.9/site-packages/executing/executing.py", line 164, in only
        raise NotOneValueFound('Expected one value, found 0')
    executing.executing.NotOneValueFound: Expected one value, found 0
